<?xml version="1.0" ?>
<robot name="telemarketingv5" xmlns:xacro="http://www.ros.org/wiki/xacro">

<xacro:include filename="$(find telemarketingv5_description)/urdf/materials.xacro" />
<xacro:include filename="$(find telemarketingv5_description)/urdf/telemarketingv5.trans" />
<xacro:include filename="$(find telemarketingv5_description)/urdf/telemarketingv5.gazebo" />


<link name="base_footprint"/>

<joint name="base_joint" type="fixed">
  <parent link="base_footprint"/>
  <child link="base_link"/>
  <origin xyz="0.0 0.0 0.010" rpy="0 0 0"/>
</joint>

<link name="base_link">
  <inertial>
    <origin xyz="0.010168634930330621 0.008829759509399987 0.4463907141626259" rpy="0 0 0"/>
    <mass value="46.60714641836719"/>
    <inertia ixx="12.436424" iyy="12.532514" izz="1.513333" ixy="-0.01684" iyz="0.015158" ixz="0.779231"/>
  </inertial>
  <visual>
    <origin xyz="0 0 0" rpy="0 0 0"/>
    <geometry>
      <mesh filename="package://telemarketingv5_description/meshes/base_link.stl" scale="0.001 0.001 0.001"/>
    </geometry>
    <material name="silver_default"/>
  </visual>
  <collision>
    <origin xyz="0 0 0" rpy="0 0 0"/>
    <geometry>
      <mesh filename="package://telemarketingv5_description/meshes/base_link.stl" scale="0.001 0.001 0.001"/>
    </geometry>
  </collision>
</link>

<link name="lidar_1">
  <inertial>
    <origin xyz="0.0002455358954546738 -1.752724045275822e-07 0.019173104184676326" rpy="0 0 0"/>
    <mass value="0.4487444263388735"/>
    <inertia ixx="0.000208" iyy="0.000205" izz="0.000295" ixy="0.0" iyz="-0.0" ixz="-1e-06"/>
  </inertial>
  <visual>
    <origin xyz="0.180069 -0.007515 -0.348266" rpy="0 0 0"/>
    <geometry>
      <mesh filename="package://telemarketingv5_description/meshes/lidar_1.stl" scale="0.001 0.001 0.001"/>
    </geometry>
    <material name="silver_default"/>
  </visual>
  <collision>
    <origin xyz="0.180069 -0.007515 -0.348266" rpy="0 0 0"/>
    <geometry>
      <mesh filename="package://telemarketingv5_description/meshes/lidar_1.stl" scale="0.001 0.001 0.001"/>
    </geometry>
  </collision>
</link>

<link name="bl_caster_1">
  <inertial>
    <origin xyz="0.013499617405453024 -0.02501899774936106 -0.031699983934426135" rpy="0 0 0"/>
    <mass value="0.1719316672512989"/>
    <inertia ixx="7.6e-05" iyy="7.9e-05" izz="6.9e-05" ixy="-0.0" iyz="-1e-05" ixz="-0.0"/>
  </inertial>
  <visual>
    <origin xyz="0.193233 0.153999 -0.062266" rpy="0 0 0"/>
    <geometry>
      <mesh filename="package://telemarketingv5_description/meshes/bl_caster_1.stl" scale="0.001 0.001 0.001"/>
    </geometry>
    <material name="silver_default"/>
  </visual>
  <collision>
    <origin xyz="0.193233 0.153999 -0.062266" rpy="0 0 0"/>
    <geometry>
      <mesh filename="package://telemarketingv5_description/meshes/bl_caster_1.stl" scale="0.001 0.001 0.001"/>
    </geometry>
  </collision>
</link>

<link name="br_caster_1">
  <inertial>
    <origin xyz="0.013500691263568065 -0.001981920532542314 -0.03169998393442165" rpy="0 0 0"/>
    <mass value="0.17193166725130055"/>
    <inertia ixx="7.6e-05" iyy="7.9e-05" izz="6.9e-05" ixy="-0.0" iyz="1e-05" ixz="0.0"/>
  </inertial>
  <visual>
    <origin xyz="0.193233 -0.201001 -0.062266" rpy="0 0 0"/>
    <geometry>
      <mesh filename="package://telemarketingv5_description/meshes/br_caster_1.stl" scale="0.001 0.001 0.001"/>
    </geometry>
    <material name="silver_default"/>
  </visual>
  <collision>
    <origin xyz="0.193233 -0.201001 -0.062266" rpy="0 0 0"/>
    <geometry>
      <mesh filename="package://telemarketingv5_description/meshes/br_caster_1.stl" scale="0.001 0.001 0.001"/>
    </geometry>
  </collision>
</link>

<link name="ul_caster_1">
  <inertial>
    <origin xyz="-0.013499308939800364 -0.001981920532537873 -0.03169998393442924" rpy="0 0 0"/>
    <mass value="0.17193166725130077"/>
    <inertia ixx="7.6e-05" iyy="7.9e-05" izz="6.9e-05" ixy="-0.0" iyz="1e-05" ixz="0.0"/>
  </inertial>
  <visual>
    <origin xyz="-0.185767 -0.201001 -0.062266" rpy="0 0 0"/>
    <geometry>
      <mesh filename="package://telemarketingv5_description/meshes/ul_caster_1.stl" scale="0.001 0.001 0.001"/>
    </geometry>
    <material name="silver_default"/>
  </visual>
  <collision>
    <origin xyz="-0.185767 -0.201001 -0.062266" rpy="0 0 0"/>
    <geometry>
      <mesh filename="package://telemarketingv5_description/meshes/ul_caster_1.stl" scale="0.001 0.001 0.001"/>
    </geometry>
  </collision>
</link>

<link name="ur_caster__1">
  <inertial>
    <origin xyz="-0.013500382364231345 0.0019810022506504543 -0.031699983934432394" rpy="0 0 0"/>
    <mass value="0.17193166725130019"/>
    <inertia ixx="7.6e-05" iyy="7.9e-05" izz="6.9e-05" ixy="-0.0" iyz="-1e-05" ixz="-0.0"/>
  </inertial>
  <visual>
    <origin xyz="-0.185767 0.180999 -0.062266" rpy="0 0 0"/>
    <geometry>
      <mesh filename="package://telemarketingv5_description/meshes/ur_caster__1.stl" scale="0.001 0.001 0.001"/>
    </geometry>
    <material name="silver_default"/>
  </visual>
  <collision>
    <origin xyz="-0.185767 0.180999 -0.062266" rpy="0 0 0"/>
    <geometry>
      <mesh filename="package://telemarketingv5_description/meshes/ur_caster__1.stl" scale="0.001 0.001 0.001"/>
    </geometry>
  </collision>
</link>

<link name="monitor1_1">
  <inertial>
    <origin xyz="-0.030787151887123484 -0.06695387994312424 -9.797491307139694e-08" rpy="0 0 0"/>
    <mass value="19.657176222199155"/>
    <inertia ixx="1.169049" iyy="0.903033" izz="0.279972" ixy="-0.007106" iyz="1e-06" ixz="0.0"/>
  </inertial>
  <visual>
    <origin xyz="0.072561 -0.099865 -1.11047" rpy="0 0 0"/>
    <geometry>
      <mesh filename="package://telemarketingv5_description/meshes/monitor1_1.stl" scale="0.001 0.001 0.001"/>
    </geometry>
    <material name="silver_default"/>
  </visual>
  <collision>
    <origin xyz="0.072561 -0.099865 -1.11047" rpy="0 0 0"/>
    <geometry>
      <mesh filename="package://telemarketingv5_description/meshes/monitor1_1.stl" scale="0.001 0.001 0.001"/>
    </geometry>
  </collision>
</link>

<link name="monitor2_1">
  <inertial>
    <origin xyz="-0.005772111727099571 -4.591409624079418e-07 0.0007583073488384162" rpy="0 0 0"/>
    <mass value="1.0873316609826422"/>
    <inertia ixx="0.018584" iyy="0.005499" izz="0.013441" ixy="0.0" iyz="0.0" ixz="-0.000938"/>
  </inertial>
  <visual>
    <origin xyz="0.1245 -0.007501 -1.663148" rpy="0 0 0"/>
    <geometry>
      <mesh filename="package://telemarketingv5_description/meshes/monitor2_1.stl" scale="0.001 0.001 0.001"/>
    </geometry>
    <material name="silver_default"/>
  </visual>
  <collision>
    <origin xyz="0.1245 -0.007501 -1.663148" rpy="0 0 0"/>
    <geometry>
      <mesh filename="package://telemarketingv5_description/meshes/monitor2_1.stl" scale="0.001 0.001 0.001"/>
    </geometry>
  </collision>
</link>

<link name="lwheel_1">
  <inertial>
    <origin xyz="1.5383367007841542e-07 0.02063704087345833 -2.65209671571065e-07" rpy="0 0 0"/>
    <mass value="2.1764840321335446"/>
    <inertia ixx="0.006799" iyy="0.013191" izz="0.006799" ixy="-0.0" iyz="-0.0" ixz="0.0"/>
  </inertial>
  <visual>
    <origin xyz="0.003308 0.185363 -0.100116" rpy="0 0 0"/>
    <geometry>
      <mesh filename="package://telemarketingv5_description/meshes/lwheel_1.stl" scale="0.001 0.001 0.001"/>
    </geometry>
    <material name="silver_default"/>
  </visual>
  <collision>
    <origin xyz="0.003308 0.185363 -0.100116" rpy="0 0 0"/>
    <geometry>
      <mesh filename="package://telemarketingv5_description/meshes/lwheel_1.stl" scale="0.001 0.001 0.001"/>
    </geometry>
  </collision>
</link>

<link name="rwheel_1">
  <inertial>
    <origin xyz="1.548622830063219e-07 -0.020637959155351965 -2.6520966649179467e-07" rpy="0 0 0"/>
    <mass value="2.176484032133543"/>
    <inertia ixx="0.006799" iyy="0.013191" izz="0.006799" ixy="-0.0" iyz="0.0" ixz="-0.0"/>
  </inertial>
  <visual>
    <origin xyz="0.003308 -0.205365 -0.100116" rpy="0 0 0"/>
    <geometry>
      <mesh filename="package://telemarketingv5_description/meshes/rwheel_1.stl" scale="0.001 0.001 0.001"/>
    </geometry>
    <material name="silver_default"/>
  </visual>
  <collision>
    <origin xyz="0.003308 -0.205365 -0.100116" rpy="0 0 0"/>
    <geometry>
      <mesh filename="package://telemarketingv5_description/meshes/rwheel_1.stl" scale="0.001 0.001 0.001"/>
    </geometry>
  </collision>
</link>

<link name="real_sense_1">
  <inertial>
    <origin xyz="-0.011196625586855385 -0.0004587946947212651 0.0030391621744179087" rpy="0 0 0"/>
    <mass value="0.03621228398825298"/>
    <inertia ixx="2.3e-05" iyy="3e-06" izz="2.3e-05" ixy="-0.0" iyz="0.0" ixz="0.0"/>
  </inertial>
  <visual>
    <origin xyz="0.154835 -0.007501 -0.683267" rpy="0 0 0"/>
    <geometry>
      <mesh filename="package://telemarketingv5_description/meshes/real_sense_1.stl" scale="0.001 0.001 0.001"/>
    </geometry>
    <material name="silver_default"/>
  </visual>
  <collision>
    <origin xyz="0.154835 -0.007501 -0.683267" rpy="0 0 0"/>
    <geometry>
      <mesh filename="package://telemarketingv5_description/meshes/real_sense_1.stl" scale="0.001 0.001 0.001"/>
    </geometry>
  </collision>
</link>

<link name="screen_1">
  <inertial>
    <origin xyz="0.012500211218237633 -4.2009023986343264e-07 -2.306741007096491e-07" rpy="0 0 0"/>
    <mass value="7.614563000001387"/>
    <inertia ixx="0.421393" iyy="0.316678" izz="0.105509" ixy="0.0" iyz="0.0" ixz="-0.0"/>
  </inertial>
  <visual>
    <origin xyz="0.133461 -0.006817 -1.11047" rpy="0 0 0"/>
    <geometry>
      <mesh filename="package://telemarketingv5_description/meshes/screen_1.stl" scale="0.001 0.001 0.001"/>
    </geometry>
    <material name="silver_default"/>
  </visual>
  <collision>
    <origin xyz="0.133461 -0.006817 -1.11047" rpy="0 0 0"/>
    <geometry>
      <mesh filename="package://telemarketingv5_description/meshes/screen_1.stl" scale="0.001 0.001 0.001"/>
    </geometry>
  </collision>
</link>

<joint name="lidar_joint" type="fixed">
  <origin xyz="-0.180069 0.007515 0.348266" rpy="0 0 0"/>
  <parent link="base_link"/>
  <child link="lidar_1"/>
</joint>

<joint name="ul_joint" type="fixed">
  <origin xyz="-0.193233 -0.153999 0.062266" rpy="0 0 0"/>
  <parent link="base_link"/>
  <child link="bl_caster_1"/>
</joint>

<joint name="ur_joint" type="fixed">
  <origin xyz="-0.193233 0.201001 0.062266" rpy="0 0 0"/>
  <parent link="base_link"/>
  <child link="br_caster_1"/>
</joint>

<joint name="br_joint" type="fixed">
  <origin xyz="0.185767 0.201001 0.062266" rpy="0 0 0"/>
  <parent link="base_link"/>
  <child link="ul_caster_1"/>
</joint>

<joint name="bl_joint" type="fixed">
  <origin xyz="0.185767 -0.180999 0.062266" rpy="0 0 0"/>
  <parent link="base_link"/>
  <child link="ur_caster__1"/>
</joint>

<joint name="monitor1_joint" type="fixed">
  <origin xyz="-0.072561 0.099865 1.11047" rpy="0 0 0"/>
  <parent link="base_link"/>
  <child link="monitor1_1"/>
</joint>

<joint name="monitor2_joint" type="fixed">
  <origin xyz="-0.1245 0.007501 1.663148" rpy="0 0 0"/>
  <parent link="base_link"/>
  <child link="monitor2_1"/>
</joint>

<joint name="left_motor" type="continuous">
  <origin xyz="-0.003308 -0.185363 0.100116" rpy="0 0 0"/>
  <parent link="base_link"/>
  <child link="lwheel_1"/>
  <axis xyz="0.0 -1.0 -0.0"/>
</joint>

<joint name="right_motor" type="continuous">
  <origin xyz="-0.003308 0.205365 0.100116" rpy="0 0 0"/>
  <parent link="base_link"/>
  <child link="rwheel_1"/>
  <axis xyz="-0.0 -1.0 0.0"/>
</joint>

<joint name="real_sense_joint" type="fixed">
  <origin xyz="-0.154835 0.007501 0.683267" rpy="0 0 0"/>
  <parent link="base_link"/>
  <child link="real_sense_1"/>
</joint>

<joint name="screen_joint" type="fixed">
  <origin xyz="-0.0609 -0.093048 0.0" rpy="0 0 0"/>
  <parent link="monitor1_1"/>
  <child link="screen_1"/>
</joint>

</robot>
